Workbook

Sheet Globals
A1: Constant | B1: Value | C1: Unit
A2: Base gold gain | B2: 2 | C2: gold / s
A3: Base max influence | B3: 100 | C3: infl
A4: Base influence gain | B4: 0.005 | C4: % of max infl / s
A5: Base reprobate suicide rate | B5: 0.0001 | C5: / s of current reprobates
A6: Base reprobate murder rate | B6: 0.0002 | C6: / s of current reprobates
A7: Player base online efficiency | B7: 1 | C7: x
A8: Player base offline efficiency | B8: 0.5 | C8: x
A9: Acolyte base efficiency | B9: 0.33 | C9: x of player
A10: Invocation base efficiency | B10: 0.05 | C10: x of player
A11: Base remaining gold % (Katabasis) | B11: 0.05 | C11: %
A12: Base remaining maleficia chance (Katabasis) | B12: 0.05 | C12: %
A13: Base remaining reprobate % (Katabasis) | B13: 0.05 | C13: %
... A20: Base VC influence output | B20: 10 | C20: Influence / s
A21: Base sigil coefficient | B21: 1
A23: Check: 8 x 180^4 | B23: =8*B15^4

Sheet Sins & Devotion
A1: Cardinal Sins, Devotion & Levels
A2: Level threshold (total devotion needed) = 180^X (cumulative), where X is level. Skill intensity = (LN(Y)^2)/65.37, where Y is total devotion.
A4: Prince | B4: Sin (Latin) | C4: English | D4: Skill | E4: Skill effect | F4: Per-level effect
A5: Beelzebub | B5: Gula | C5: Gluttony | D5: Insatiability | E5: + online player efficiency | F5: -25% Bad, Terrible and Apocalyptic chance (additive, lvl 4 you have 0% negative outcome chances)
A6: Asmodeus | B6: Luxuria | C6: Lust | D6: Seduction | E6: + reprobate generation rate | F6: +100% overall Logos efficiency (mult) /lvl; unlocks Logos actions and toggles
A7: Mammon | B7: Avaritia | C7: Greed | D7: Golden Hand | E7: + gold gain rate | F7: +12.5% remaining gold % / level
A8: Leviathan | B8: Tristitia | C8: Sorrow | D8: Resignation | E8: + acolyte efficiency | F8: +12.5% remaining reprobate % /lvl
A9: Satan | B9: Ira | C9: Wrath | D9: Retribution | E9: + invocation efficiency | F9: +100% overall Decimatio efficiency (mult); unlocks Decimatio actions and toggles
A10: Belphegor | B10: Acedia | C10: Sloth | D10: Procrastination | E10: + offline player efficiency | F10: offline mult 1.0000002^(s*(L^2)), where L is level and s is seconds offline in a row
A11: Rosier | B11: Vanagloria | C11: Vainglory | D11: Acclaim | E11: + max influence | F11: *1.33 influence gain rate /lvl
A12: Lucifer | B12: Superbia | C12: Pride | D12: Morning Star | E12: + Stellar chance | F12: +12.5% remaining maleficia chance /lvl
A15: Skill intensity sampled over total Devotion x (applies multiplicatively)
A16: Devotion x | B16: Intensity
A17: 1 | B17: =(LN(A17)^2)/65.37
A18: 10 | B18: =(LN(A18)^2)/65.37
A19: 50 | B19: =(LN(A19)^2)/65.37
A20: 180 | B20: =(LN(A20)^2)/65.37
A21: 32400 | B21: =(LN(A21)^2)/65.37
A22: 5832000 | B22: =(LN(A22)^2)/65.37
A23: 1049760000 | B23: =(LN(A23)^2)/65.37

Sheet Sigils
A1: Sigils — the 72 Goetia
A2: Sigils curves can be linear, log or sqrt. Effect at N souls = base_coeff × curve(N). #32 Semet unlocks at all sins ≥2. The values of log and sqrt curves apply as a percentage increase or decrease, linear curves apply as a flat increase .
A4: # | B4: Sigil | C4: Demonological role | D4: In-game effect | E4: Curve | F4: Base coeff | G4: Sample N | H4: Yield @ N
A5: 1 | B5: Bael | C5: Changeling; invisibility | D5: -Opera negative outcome chance | E5: sqrt | F5: =0.0001*Globals!$B$21 | G5: 100000000 | H5: =IF(F5="","",F5*IF(E5="linear",G5,IF(E5="log",LN(G5+1),SQRT(G5))))
A6: 2 | B6: Agares | C6: Earthquakes; retrieval | D6: +chance to duplicate output of Indagatio | E6: sqrt | F6: =0.0001*Globals!$B$21 | G6: 100 | H6: =IF(F6="","",F6*IF(E6="linear",G6,IF(E6="log",LN(G6+1),SQRT(G6))))
A7: 3 | B7: Vassago | C7: Foresees past/future | D7: +chance profane & anathema maleficia | E7: sqrt | F7: =0.0001*Globals!$B$21 | G7: 100000 | H7: =IF(F7="","",F7*IF(E7="linear",G7,IF(E7="log",LN(G7+1),SQRT(G7))))
A8: 4 | B8: Samigina | C8: Accounts of the dead | D8: +Tristitia invocation effectiveness | E8: sqrt | F8: =0.0001*Globals!$B$21 | G8: 10000 | H8: =IF(F8="","",F8*IF(E8="linear",G8,IF(E8="log",LN(G8+1),SQRT(G8))))
A9: 5 | B9: Marbas | C9: Reveals secrets | D9: +Indagatio postitive outcome chance | E9: sqrt | F9: =0.0001*Globals!$B$21 | G9: 100000 | H9: =IF(F9="","",F9*IF(E9="linear",G9,IF(E9="log",LN(G9+1),SQRT(G9))))
A10: 6 | B10: Valefor | C10: Thievery | D10: +online gold gain rate | E10: sqrt | F10: =0.0001*Globals!$B$21 | G10: 100000000 | H10: =IF(F10="","",F10*IF(E10="linear",G10,IF(E10="log",LN(G10+1),SQRT(G10))))
A11: 7 | B11: Aamon | C11: Reproduction/life | D11: + online reprobate generation rate | E11: sqrt | F11: =0.0001*Globals!$B$21 | G11: 100 | H11: =IF(F11="","",F11*IF(E11="linear",G11,IF(E11="log",LN(G11+1),SQRT(G11))))
A12: 8 | B12: Barbatos | C12: Songs of animals | D12: +Gula invocation effectiveness | E12: sqrt | F12: =0.0001*Globals!$B$21 | G12: 100 | H12: =IF(F12="","",F12*IF(E12="linear",G12,IF(E12="log",LN(G12+1),SQRT(G12))))
A13: 9 | B13: Paimon | C13: Loyalty; returning servants | D13: -influence costs | E13: sqrt | F13: =0.00005*Globals!$B$21 | G13: 100000000 | H13: =IF(F13="","",F13*IF(E13="linear",G13,IF(E13="log",LN(G13+1),SQRT(G13))))
A14: 10 | B14: Buer | C14: Good familiars | D14: +familiar effectiveness | E14: sqrt | F14: =0.0001*Globals!$B$21 | G14: 100 | H14: =IF(F14="","",F14*IF(E14="linear",G14,IF(E14="log",LN(G14+1),SQRT(G14))))
A15: 11 | B15: Gusion | C15: Reconciles enemies | D15: +Vitium Compositum effects (does not affect gold and influence outcomes) | E15: sqrt | F15: =0.0001*Globals!$B$21 | G15: 100 | H15: =IF(F15="","",F15*IF(E15="linear",G15,IF(E15="log",LN(G15+1),SQRT(G15))))
A16: 12 | B16: Sitri | C16: Love | D16: +Vitium Mercatura reprobate generation rate | E16: sqrt | F16: =0.0001*Globals!$B$21 | G16: 100000 | H16: =IF(F16="","",F16*IF(E16="linear",G16,IF(E16="log",LN(G16+1),SQRT(G16))))
A17: 13 | B17: Beleth | C17: Attended by trumpets | D17: +Decimatio positive outcome chance | E17: sqrt | F17: =0.0001*Globals!$B$21 | G17: 100 | H17: =IF(F17="","",F17*IF(E17="linear",G17,IF(E17="log",LN(G17+1),SQRT(G17))))
A18: 14 | B18: Leraie | C18: Putrefies wounds | D18: +chance a murder triggers a suicide | E18: sqrt | F18: =0.0001*Globals!$B$21 | G18: 100 | H18: =IF(F18="","",F18*IF(E18="linear",G18,IF(E18="log",LN(G18+1),SQRT(G18))))
A19: 15 | B19: Eligos | C19: Favour of important people | D19: +offline influence gain rate | E19: sqrt | F19: =0.0001*Globals!$B$21 | G19: 100 | H19: =IF(F19="","",F19*IF(E19="linear",G19,IF(E19="log",LN(G19+1),SQRT(G19))))
A20: 16 | B20: Zepar | C20: Makes women barren | D20: +offline reprobate generation rate | E20: sqrt | F20: =0.0001*Globals!$B$21 | G20: 100 | H20: =IF(F20="","",F20*IF(E20="linear",G20,IF(E20="log",LN(G20+1),SQRT(G20))))
A21: 17 | B21: Botis | C21: Past and future | D21: -Logos negative outcome chance | E21: sqrt | F21: =0.0001*Globals!$B$21 | G21: 100 | H21: =IF(F21="","",F21*IF(E21="linear",G21,IF(E21="log",LN(G21+1),SQRT(G21))))
A22: 18 | B22: Bathin | C22: Transport | D22: +acolyte action efficiency | E22: sqrt | F22: =0.0001*Globals!$B$21 | G22: 100 | H22: =IF(F22="","",F22*IF(E22="linear",G22,IF(E22="log",LN(G22+1),SQRT(G22))))
A23: 19 | B23: Sallos | C23: Peace, idleness | D23: +offline gold gain rate | E23: sqrt | F23: =0.0001*Globals!$B$21 | G23: 100 | H23: =IF(F23="","",F23*IF(E23="linear",G23,IF(E23="log",LN(G23+1),SQRT(G23))))
A24: 20 | B24: Purson | C24: Hidden treasures | D24: +remaining gold % (flat) | E24: log | F24: 1 | G24: 100000000 | H24: =IF(F24="","",F24*IF(E24="linear",G24,IF(E24="log",LN(G24+1),SQRT(G24))))
A25: 21 | B25: Marax | C25: Stops, delays | D25: +offline action efficiency | E25: sqrt | F25: =0.0001*Globals!$B$21 | G25: 100 | H25: =IF(F25="","",F25*IF(E25="linear",G25,IF(E25="log",LN(G25+1),SQRT(G25))))
A26: 22 | B26: Ipos | C26: Valiant, tactical | D26: -Decimatio negative outcome chance | E26: sqrt | F26: =0.0001*Globals!$B$21 | G26: 100 | H26: =IF(F26="","",F26*IF(E26="linear",G26,IF(E26="log",LN(G26+1),SQRT(G26))))
A27: 23 | B27: Aim | C27: Sets fire | D27: +Murder rate | E27: sqrt | F27: =0.0001*Globals!$B$21 | G27: 100 | H27: =IF(F27="","",F27*IF(E27="linear",G27,IF(E27="log",LN(G27+1),SQRT(G27))))
A28: 24 | B28: Naberius | C28: Arts & rhetoric | D28: +Vitium Compositum effects | E28: sqrt | F28: =0.0001*Globals!$B$21 | G28: 100 | H28: =IF(F28="","",F28*IF(E28="linear",G28,IF(E28="log",LN(G28+1),SQRT(G28))))
A29: 25 | B29: Glasya-Labolas | C29: Manslaughter | D29: +Murder rate (flat) | E29: log | F29: 0.001 | G29: 100000 | H29: =IF(F29="","",F29*IF(E29="linear",G29,IF(E29="log",LN(G29+1),SQRT(G29))))
A30: 26 | B30: Bune | C30: Wisdom | D30: +Vanagloria invocation effectiveness | E30: sqrt | F30: =0.0001*Globals!$B$21 | G30: 1000 | H30: =IF(F30="","",F30*IF(E30="linear",G30,IF(E30="log",LN(G30+1),SQRT(G30))))
A31: 27 | B31: Ronove | C31: Harvests souls near death | D31: +Suicide rate | E31: sqrt | F31: 0.0001 | G31: 100 | H31: =IF(F31="","",F31*IF(E31="linear",G31,IF(E31="log",LN(G31+1),SQRT(G31))))
A32: 28 | B32: Berith | C32: Covenant | D32: +Superbia invocation effectiveness | E32: sqrt | F32: 0.0001 | G32: 100 | H32: =IF(F32="","",F32*IF(E32="linear",G32,IF(E32="log",LN(G32+1),SQRT(G32))))
A33: 29 | B33: Astaroth | C33: Secrets, all times | D33: +Stellar chance for Indagatio | E33: sqrt | F33: 0.0001 | G33: 100 | H33: =IF(F33="","",F33*IF(E33="linear",G33,IF(E33="log",LN(G33+1),SQRT(G33))))
A34: 30 | B34: Forneus | C34: Rhetoric | D34: +invoking power (flat) | E34: log | F34: =0.5*Globals!$B$21 | G34: 100000000 | H34: =IF(F34="","",F34*IF(E34="linear",G34,IF(E34="log",LN(G34+1),SQRT(G34))))
A35: 31 | B35: Foras | C35: Logic, invisibility | D35: +offline accrual window | E35: sqrt | F35: 2.5e-05 | G35: 100000000 | H35: =IF(F35="","",F35*IF(E35="linear",G35,IF(E35="log",LN(G35+1),SQRT(G35))))
A36: 32 | B36: Semet | C36: Final destiny | D36: +sigil effect % | E36: log | F36: =0.01*Globals!$B$21 | G36: 5832000 | H36: =IF(F36="","",F36*IF(E36="linear",G36,IF(E36="log",LN(G36+1),SQRT(G36))))
A37: 33 | B37: Gaap | C37: Makes men stupid | D37: +maleficia effect % | E37: log | F37: =0.01*Globals!$B$21 | G37: 100000000 | H37: =IF(F37="","",F37*IF(E37="linear",G37,IF(E37="log",LN(G37+1),SQRT(G37))))
A38: 34 | B38: Furfur | C38: Love; storms | D38: +Luxuria invocation effectiveness | E38: sqrt | F38: 0.0001 | G38: 100000 | H38: =IF(F38="","",F38*IF(E38="linear",G38,IF(E38="log",LN(G38+1),SQRT(G38))))
A39: 35 | B39: Marchosias | C39: Faithful follower | D39: +max influence | E39: sqrt | F39: 0.0001 | G39: 100 | H39: =IF(F39="","",F39*IF(E39="linear",G39,IF(E39="log",LN(G39+1),SQRT(G39))))
A40: 36 | B40: Stolas | C40: Astronomy, herbs | D40: -chance Common maleficia in Indagatio | E40: sqrt | F40: 0.0001 | G40: 100 | H40: =IF(F40="","",F40*IF(E40="linear",G40,IF(E40="log",LN(G40+1),SQRT(G40))))
A41: 37 | B41: Phenex | C41: Phoenix; sings | D41: -Emptio negative outcome chance | E41: sqrt | F41: 0.0001 | G41: 100 | H41: =IF(F41="","",F41*IF(E41="linear",G41,IF(E41="log",LN(G41+1),SQRT(G41))))
...

Sheet Logos
A1: Logos — Tempting
A2: Action efficiency modifies costs and positive outcomes by the same %; does NOT affect action time.
A4: Suggestion — one-shot 5s, 5 influence; Luxuria 1 enables toggle
A5: Early-game reprobate source.
A6: Tier | B6: Base prob % | C6: Effect
A7: Stellar | B7: 0.001 | C7: +randint(4,8) reprobate
A8: Excellent | B8: 0.099 | C8: +randint(2,4) reprobate
A9: Good | B9: 0.25 | C9: +1 reprobate
A10: Neutral | B10: 0.35 | C10: nothing
A11: Bad | B11: 0.2 | C11: -1 reprobate
A12: Terrible | B12: 0.099 | C12: lose 9% reprobates
A13: Apocalyptic | B13: 0.001 | C13: Lose 50% reprobates
A14: SUM check | B14: =SUM(B7:B13) | C14: (should = 100% for fully-specified distributions)
A16: Logismoi — one-shot 5s, 25 influence; unlock Luxuria 2, toggle Luxuria 3
A17: Mid-game reprobate source.
A18: Tier | B18: Base prob % | C18: Effect
A19: Stellar | B19: 0.01 | C19: +3% current reprobates
A20: Excellent | B20: 0.15 | C20: +randint(20,58) reprobates
A21: Good | B21: 0.3 | C21: +randint(10,29) reprobates
A22: Neutral | B22: 0.3 | C22: nothing
A23: Bad | B23: 0.17 | C23: -1 reprobate
A24: Terrible | B24: 0.069 | C24: lose 9% reprobates
A25: Apocalyptic | B25: 0.001 | C25: Lose 50% reprobates
A26: SUM check | B26: =SUM(B19:B25) | C26: (should = 100% for fully-specified distributions)
A28: Imperium — one-shot 10s, 100 influence; unlock Luxuria 3, toggle Luxuria 4
A29: Late-game; outcome is fixed (player in control).
A30: Tier | B30: Base prob % | C30: Effect
A31: Stellar | B31: 0.035 | C31: +3% current souls
A32: Excellent | B32: 0.18 | C32: +3% current reprobates
A33: Good | B33: 0.21 | C33: +randint(100,1000) reprobates
A34: Neutral | B34: 0.235 | C34: nothing
A35: Bad | B35: 0.15 | C35: -1 reprobate
A36: Terrible | B36: 0.155 | C36: Lose 5% reprobates
A37: Apocalyptic | B37: 0.035 | C37: Lose 50% reprobates
A38: SUM check | B38: =SUM(B31:B37) | C38: (should = 100% for fully-specified distributions)

Sheet Decimatio
A1: Decimatio — Culling
A2: Action efficiency modifies costs and positive outcomes by the same %; does NOT affect action time.
A4: Caedis — one-shot 10s, 100 gold; Ira 1 enables toggle
A5: Early soul source.
A6: Tier | B6: Base prob % | C6: Effect
A7: Stellar | B7: 0.01 | C7: Randint(15,45) reprobates die (+= souls)
A8: Excellent | B8: 0.05 | C8: Randint(3,9) reprobates die (+= souls)
A9: Good | B9: 0.66 | C9: 1 reprobate dies (+= souls)
A10: Neutral | B10: 0.15 | C10: gold spent, no outcome
A11: Bad | B11: 0.1 | C11: 5% gold loss.
A12: Terrible | B12: 0.02 | C12: 15% gold loss.
A13: Apocalyptic | B13: 0.01 | C13: 33% gold loss and 25% total reprobate loss.
A14: SUM check | B14: =SUM(B7:B13) | C14: (should = 100% for fully-specified distributions)
A16: Pogrom — one-shot ~60s, 1000 gold; unlock Ira 2, toggle Ira 3
A17: Mass cull.
A18: Tier | B18: Base prob % | C18: Effect
A19: Stellar | B19: 0.015 | C19: 2.5 % reprobates die (+= souls)
A20: Excellent | B20: 0.06 | C20: 1% reprobates die (+= souls)
A21: Good | B21: 0.6 | C21: 0.1% reprobates die (+= souls)
A22: Neutral | B22: 0.15 | C22: gold spent, no outcome
A23: Bad | B23: 0.1 | C23: 5% gold loss
A24: Terrible | B24: 0.06 | C24: Lose 15% reprobates
A25: Apocalyptic | B25: 0.015 | C25: 66% gold loss and 50% reprobate loss.
A26: SUM check | B26: =SUM(B19:B25) | C26: (should = 100% for fully-specified distributions)
A28: Purgatio — one-shot ~360s, 1000000; unlock Ira 3, toggle Ira 4
A29: Soul farming.
A30: Tier | B30: Base prob % | C30: Effect
A31: Stellar | B31: 0.025 | C31: 25% reprobates die (+= souls)
A32: Excellent | B32: 0.1 | C32: 10% reprobates die (+= souls)
A33: Good | B33: 0.3 | C33: 1% reprobates die (+= souls)
A34: Neutral | B34: 0.3 | C34: gold spent, no outcome
A35: Bad | B35: 0.15 | C35: 5% gold loss
A36: Terrible | B36: 0.1 | C36: Lose 100% gold
A37: Apocalyptic | B37: 0.025 | C37: Lose 100% gold and reprobates
A38: SUM check | B38: =SUM(B31:B37) | C38: (should = 100% for fully-specified distributions)

Sheet Indagatio & Emptio
A1: Indagatio (search) & Emptio (purchase)
A2: Action effect reduces action time needed for Indagatio and Emptio
A4: Indagatio tier | B4: Prob % | C4: Effect | D4: Indagatio time
A5: Stellar | B5: 0.001 | C5: Random anathema maleficium found | D5: 300 s
A6: Excellent | B6: 0.049 | C6: Random profane maleficium found
A7: Good | B7: 0.25 | C7: Random rare maleficium found
A8: Neutral | B8: 0.5 | C8: Random common maleficium found
A9: Bad | B9: 0.15 | C9: lose time
A10: Terrible | B10: 0.049 | C10: Lose 15% current gold
A11: Apocalyptic | B11: 0.001 | C11: Lose 80% current gold
A12: SUM | B12: =SUM(B5:B11)
A14: Emptio tier | B14: Prob % | C14: Effect | D14: Emptio time
A15: Stellar | B15: 0.01 | C15: Free maleficia | D15: 60 s
A16: Excellent | B16: 0.04 | C16: purchase at 25% price
A17: Good | B17: 0.1 | C17: purchase at 50% price
A18: Neutral | B18: 0.7 | C18: purchase at 100% price
A19: Bad | B19: 0.1 | C19: lose time
A20: Terrible | B20: 0.049 | C20: lose time and gold
A21: Apocalyptic | B21: 0.001 | C21: lose 50% total gold
A22: SUM | B22: =SUM(B15:B21)

Sheet Maleficia
A1: Maleficia — occult items
A2: Discovered via Indagatio, bought via Emptio. Remain across lifetimes on remaining-roll.
A4: Maleficium | B4: Type | C4: Rarity | D4: Invoking power | E4: Stack cap | F4: Effect | G4: Affected by maleficia effect increases?
A5: Spear of Longinus | B5: Enhancer | C5: Anathema | D5: 0 | E5: 1 | F5: x3 max influence | G5: yes
A6: Mark of Cain | B6: Enhancer | C6: Anathema | D6: 0 | E6: 1 | F6: 3x murder rate | G6: yes
A7: Thirty Pieces of Silver | B7: Enhancer | C7: Anathema | D7: 0 | E7: 1 | F7: Increases gold gain by 0.001% per current gold | G7: yes
A8: Solomon's Ring | B8: Enhancer | C8: Anathema | D8: 0 | E8: 1 | F8: *1.66 sigil effect | G8: yes
A9: Red Robe | B9: Power source | C9: Common | D9: 1 | E9: 1 | F9: +1 invoking power | G9: no
A10: Sulfur Censer | B10: Power source | C10: Common | D10: 2 | E10: 1 | F10: +2 invoking power | G10: no
A11: Black Candles | B11: Enhancer, stackable | C11: Common | D11: 0 | E11: 5 | F11: +5% invocation effect per candle | G11: yes
A12: The Dadu | B12: Oracular, power source | C12: Common | D12: 1 | E12: 1 | F12: reveal Decimatio distribution | G12: no
A13: Hollow Effigy | B13: Oracular, power source | C13: Common | D13: 1 | E13: 1 | F13: reveal Logos distribution | G13: no
A14: Black Salt Pouch | B14: Power source, stackable | C14: Common | D14: 1 | E14: ∞ | F14: +1 invoking power | G14: no
A15: Iron Nails | B15: Power source, stackable | C15: Common | D15: 1 | E15: ∞ | F15: +1% sigil effects (mult); +1 power | G15: no
A16: Witch Bottle | B16: Power source | C16: Common | D16: 2 | E16: 1 | F16: +2 invoking power | G16: no
A17: Crossroads Dirt | B17: Oracular, power source | C17: Common | D17: 1 | E17: 1 | F17: reveal Emptio distribution | G17: no
A18: Mandrake Root | B18: Power source | C18: Common | D18: 2 | E18: 1 | F18: +2 invoking power | G18: no
A19: Crow Feather | B19: Oracular, power source | C19: Common | D19: 1 | E19: 1 | F19: reveal Indagatio distribution | G19: no
A20: Witch Ladder | B20: Enhancer | C20: Common | D20: 0 | E20: 1 | F20: *1.05 suicide rate | G20: yes
A21: Adder Stone | B21: Enhancer | C21: Common | D21: 0 | E21: 1 | F21: *1.05 reprobate generation | G21: yes
A22: Poppet | B22: Enhancer | C22: Common | D22: 0 | E22: 1 | F22: *1.05 murder rate | G22: yes
A23: The Voynich Manuscript | B23: Enhancer, power source | C23: Profane | D23: 6 | E23: 1 | F23: *1.66 Logos efficiency | G23: yes
A24: Obsidian Mirror | B24: Oracular, power source | C24: Profane | D24: 8 | E24: 1 | F24: reveal ALL Opera distributions | G24: no
A25: Defixio | B25: Targeted, stackable | C25: Profane | D25: 0 | E25: ∞ | F25: Single-use: culls reprobates, e^s ramp | G25: yes
A26: Galdrabók | B26: Enhancer | C26: Profane | D26: 0 | E26: 1 | F26: *1.15 murder rate | G26: yes
A27: Codex Gigas | B27: Enhancer | C27: Profane | D27: 0 | E27: 1 | F27: x1.33 influence gain rate | G27: yes
A28: Ars Serpens | B28: Enhancer, power source | C28: Rare | D28: 2 | E28: 1 | F28: *1.33 Logos efficiency | G28: yes
A29: Ritual Dagger | B29: Enhancer, power source | C29: Rare | D29: 2 | E29: 1 | F29: *1.33 Decimatio efficiency | G29: yes
A30: Blood Chalk | B30: Power source | C30: Rare | D30: 4 | E30: 1 | F30: +4 invoking power | G30: no
A31: Blackthorn Wand | B31: Power source | C31: Rare | D31: 4 | E31: 1 | F31: +4 invoking power | G31: no
A32: Hand of Glory | B32: Targeted, stackable | C32: Rare | D32: 0 | E32: ∞ | F32: single-use: +100% reprobate generation rate for 1h | G32: yes
A33: Dybbuk Box | B33: Power source | C33: Rare | D33: 3 | E33: 1 | F33: +3 invoking power | G33: no
A35: Maleficium rarity | B35: Price (gold)
A36: Anathema | B36: Randint(66666, 93456)
A37: Profane | B37: Randint(6666, 23754)
A38: Rare | B38: Randint(1000, 3333)
A39: Common | B39: Randint(100, 1000)

Sheet Invocatio
A1: Invocatio — Summoning
A2: Persistent unless noted; all dispelled on Katabasis. You can only have one Apex invocation active. You can only have one Familiar invocation active. You can have any number of normal invocations active. All invocations visually disappear when dispelled.
A4: Invocation | B4: Cardinal Sin | C4: Invoking power required | D4: Sin lvl | E4: Type | F4: Cost | G4: Effect (summary) | H4: Efficiency (compared to player base efficiency) | I4: Visually displayed once invoked? | J4: Idle movement?
A5: Familiar | B5: — | C5: ≥2 | D5: — | E5: Special | F5: none | G5: Flat +33% player eff; Familiar action efficiency applies to Indagatio. | H5: =0.2*Globals!$B$10 | I5: Always in the Studio, sitting besides the door. | J5: No
A6: Lemure | B6: Acedia | C6: ≥3 | D6: Acedia 1 | E6: Normal | F6: 1% of max influence / s | G6: Action efficiency applies as additive offline gain rate | H6: =0.5*Globals!$B$10 | I6: In the Altar room. | J6: No
A7: Morpheus | B7: Acedia | C7: ≥10 | D7: Acedia 3 | E7: Apex | F7: 90% current souls & gold | G7: full freeze; next Katabasis 100% gold/maleficia, keep Emptio list. | H7: - | I7: Floating over the Altar in the Altar room, always if active. Overrides other invocations visually. | J7: Yes
A8: Plutus | B8: Avaritia | C8: ≥5 | D8: Avaritia 2 | E8: Normal | F8: 3 infl/s | G8: Action efficiency applies as increase to Vitium Mercatura output | H8: =1*Globals!$B$10 | I8: 10% times in the Studio. | J8: No
A9: Midas | B9: Avaritia | C9: ≥7 | D9: Avaritia 3 | E9: Apex | F9: - | G9: x3 gold gain; x33 Apocalyptic chance | H9: - | I9: 10% times in the Studio. | J9: No
A10: Upir | B10: Gula | C10: ≥3 | D10: Gula 1 | E10: Normal | F10: 1 infl/s | G10: Upir action efficiency applies to Caedis | H10: =1*Globals!$B$10 | I10: 10% times in the invocation room | J10: No
A11: Aurevora | B11: Gula | C11: ≥7 | D11: Gula 3 | E11: Apex | F11: (1% * e^s) gold/s | G11: Eats 10 gold/s rising exponentially with time, one tenth of the exponential is applied as an increase to player action efficiency; dispel at 0 gold | H11: - | I11: Immediately when invoked, overrides other invocations in the room. | J11: No
A12: Imp | B12: Ira | C12: ≥2 | D12: Ira 1 | E12: Normal | F12: 10 gold /s | G12: Imp action efficiency applies to Caedis | H12: =1*Globals!$B$10 | J12: No
A13: Harpy | B13: Ira | C13: ≥4 | D13: Ira 2 | E13: Normal | F13: 5 infl/s | G13: Action efficiency applies as to Progrom | H13: =1*Globals!$B$10 | I13: 10% times in the Studio window. | J13: No
A14: Erinyes | B14: Ira | C14: ≥10 | D14: Ira 3 | E14: Apex | F14: - | G14: kill all reprobates; next Katabasis 0% gold and maleficia remaining; x2 overall action efficiency permanently; | H14: - | I14: In the Altar room, always if active. Overrides other invocations visually. | J14: No
A15: Lamia | B15: Luxuria | C15: ≥4 | D15: Luxuria 2 | E15: Normal | F15: 3 infl/s | G15: Lamia action efficiency applies to Logismoi | H15: =1*Globals!$B$10 | I15: Immediately when invoked, cannot visually show more than 1 | J15: No
A16: Succubus | B16: Luxuria | C16: ≥9 | D16: Luxuria 3 | E16: Apex | F16: 99% current gold gain / s | G16: Succubus action efficiency applies to Imperium | H16: =19.8*Globals!$B$10 | I16: 10% times in the invocation room | J16: No
A17: Behemoth | B17: Superbia | C17: ≥2 | D17: Superbia 1 | E17: Normal | F17: 5% current gold and influcence gain / s | G17: Action efficiency applies as additive increase to Stellar chance across Opera | H17: =0.001*Globals!$B$10 | J17: No
A18: Doppelgaenger | B18: Superbia | C18: ≥8 | D18: Superbia 3 | E18: Apex | F18: 50% current influence gain/s | G18: +50% player efficiency | H18: - | J18: No
A19: Nightmare | B19: Tristitia | C19: ≥3 | D19: Tristitia 1 | E19: Normal | F19: 3 infl/s | G19: Action efficiency applies as additive increase to base suicide rate | H19: =0.001*Globals!$B$10 | I19: In the Altar room. | J19: No
A20: Astiwihad | B20: Tristitia | C20: ≥10 | D20: Tristitia 3 | E20: Apex | F20: 100% current influence gain/s | G20: 0.01%/s chance all reprobates suicide | H20: -% | I20: In the Altar room. | J20: No
A21: Fama | B21: Vanagloria | C21: ≥3 | D21: Vanagloria 1 | E21: Normal | F21: 25% current gold / s | G21: Fama action efficiency applies as additive increase to influence gain rate | H21: =1*Globals!$B$10 | J21: No
A22: Specunitas | B22: Vanagloria | C22: ≥9 | D22: Vanagloria 3 | E22: Apex | F22: 99% current gold gain / s | G22: X2 influence gain / s | H22: - | I22: 10% times in the Studio. | J22: No

Sheet Vitium Mercatura
A1: Vitium Mercatura — the Mercatus system (eight trades, exactly one per Cardinal Sin)
A2: Replaces the legacy 32-business catalog. Each trade has one integer depth d ≥ 0; deepening is an instant gold purchase. Source: docs/vm-vc-redesign-spec.md
A4: Constant | B4: Value | C4: Unit / note
A5: Invest cost seed (C0) | B5: 50 | C5: gold — depth 0 → 1 costs floor(C0)
A6: Invest cost ratio (r) | B6: 1.6 | C6: x per depth — investCost(d) = floor(C0 × r^d)
A7: Cumulative invest cost | C7: closed form C0 × (r^d − 1)/(r − 1) — derive, never store
A8: Penetration steepness (a) | B8: 0.15 | C8: penetration(d) = 1 − e^(−a·d)
A9: Spend per capita | B9: 0.1 | C9: gold / s / reprobate (per trade, at full penetration)
A10: Generation per depth | B10: 0.02 | C10: reprobates / s per depth of one trade
A11: Divest fraction | B11: =Globals!$B$14 | C11: % of divested depths’ cumulative cost (Vine #45 keeps modifying it)
A12: Depth cap per Sin level | B12: 10 | C12: cap = 10 × sinLevel (unlock at Sin level 1)
A13: Foedus depth step | B13: 10 | C13: tier = min(floor(min member depth / step), max tier)
A14: Max Foedus tier | B14: 4
A15: Foedus upkeep discount per tier | B15: 0.125 | C15: VC upkeep × (1 − discount × tier); tier 4 → ×0.5
A16: Foedus revenue bonus per tier | B16: 0.05 | C16: member trade take × (1 + bonus × tier) while VC active; shared-Sin VCs stack ×
A18: Revenue / generation (per trade)
A19: revenue/s = spendPerCapita × reprobates × penetration(d); total replaces businessGoldPerSecond at tick step 1, × vitiumMercaturaOutputMul, × goldRateMul
A20: generation/s = genPerDepth × d, into the generation pool, × vitiumMercaturaOutputMul (Foedus bonus applies to revenue only)
A21: Katabasis: all trades auto-divest at the divest fraction into gold BEFORE the remaining-gold roll; depths reset to 0
A23: Foedus opt-out flags (per VC, default all-on = FALSE)
A24: Ceremony | B24: Foedus opt-out
A25: Charity | B25: =FALSE()
A26: Gala | B26: =FALSE()
A27: Bacchanal | B27: =FALSE()
A28: Dolce Far Niente | B28: =FALSE()
A29: Enraging broadcast | B29: =FALSE()
A30: Doom gathering | B30: =FALSE()
A31: Vegas | B31: =FALSE()
A32: Crusade | B32: =FALSE()
A33: Panvitium | B33: =FALSE()
A35: Per-Sin signature clauses (slice 2 — §1.5 table as amended in session)
A36: Mercatus | B36: Constant | C36: Clause
A37: Gulae | B37: 1.25 | C37: spendPerCapita ×1.25 for this trade (its revenue ×1.25)
A38: Luxuriae | B38: 1.25 | C38: its generation ×1.25
A39: Avaritiae | B39: 0.995 | C39: each depth bargains the next 0.5% cheaper — COMPOUNDS (effective ratio r × 0.995 ≈ 1.592); refunds on the same basis
A40: Tristitiae | B40: 0.00825 | C40: +0.825% reprobate suicide-rate mul per depth (global)
A41: Irae | B41: 0.00825 | C41: +0.825% murder-rate mul per depth (global)
A42: Acediae | B42: 0.00825 | C42: revenue exempt from the ×0.5 offline efficiency; +0.825% offline gain rate mul per depth
A43: Vanagloriae | B43: 0.0025 | C43: +0.25% of effective max influence as flat influence/s per full 10 depths (stepped)
A44: Superbiae | B44: 1.25 / 1.33 | C44: depths ×1.25 dearer; its revenue ×1.33 and its generation ×1.33
...

Sheet Vitium Compositum
A1: Vitium Compositum — multi-Sin toggles
A2: Tick 1s, action time unaffected by efficiency. Efficiency affects costs and outcomes.
A4: Name | B4: Sin combination | C4: Min sin lvl | D4: Gold cost /s | E4: Influence cost /s | F4: Gold out /s | G4: Influence out /s | H4: Effect
A5: Charity | B5: Avaritia + Vanagloria | C5: 1 | D5: =1*Globals!$B$17 | E5: =2.5*Globals!$B$18 | F5: =2*Globals!$B$19 | G5: =0*Globals!$B$20 | H5: -
A6: Gala | B6: Superbia + Vanagloria | C6: 1 | D6: =2.5*Globals!$B$17 | E6: =0*Globals!$B$18 | F6: =0*Globals!$B$19 | G6: =2*Globals!$B$20 | H6: -
A7: Bacchanal | B7: Gula + Luxuria | C7: 1 | D7: =1*Globals!$B$17 | E7: =1*Globals!$B$18 | F7: =0*Globals!$B$19 | G7: =0*Globals!$B$20 | H7: Increases online reprobate generation rate by 10%
A8: Dolce Far Niente | B8: Gula + Acedia | C8: 1 | D8: =0*Globals!$B$17 | E8: =0*Globals!$B$18 | F8: =0*Globals!$B$19 | G8: =0*Globals!$B$20 | H8: Increases offline gold gain and offline reprobate generation rates by 1%
A9: Enraging broadcast | B9: Ira + Tristitia | C9: 1 | D9: =0*Globals!$B$17 | E9: =2.5*Globals!$B$18 | F9: =0*Globals!$B$19 | G9: =0*Globals!$B$20 | H9: Increases murder rate by 10%
A10: Doom gathering | B10: Tristitia + Acedia | C10: 1 | D10: =1*Globals!$B$17 | E10: =1*Globals!$B$18 | F10: =0*Globals!$B$19 | G10: =0*Globals!$B$20 | H10: Increases suicide rate by 10%
A11: Vegas | B11: Luxuria + Avaritia + Gula + Acedia | C11: 2 | D11: 50% current gold gain / s | E11: 0 | F11: 0 | G11: 1% current gold gain / s | H11: -
A12: Crusade | B12: Superbia + Ira + Vanagloria + Tristitia | C12: 2 | D12: 0 | E12: 50% current influence gain / s | F12: 1000% current influence gain / s | G12: 0 | H12: -
A13: Panvitium | B13: ALL sins ≥ 3 | C13: 3 | D13: 10*Globals!$B$17*e^(t) | E13: 10*Globals!$B$18*e^(t) | F13: =0*Globals!$B$19 | G13: =0*Globals!$B$20 | H13: The “t” is seconds active – costs and conversion rate grow exponentially with time. Generates souls /s based on current reprobates.

Sheet Acolytes
A1: Acolytes
A2: Count is driven by max influence; run delegated actions at base 33% efficiency (modifiable). Max 4 shown in room. Cannot run actions requiring specific maleficia.
A4: Max influence threshold | B4: Acolytes unlocked | C4: Per-acolyte efficiency | D4: Note
A5: 110 | B5: 1 | C5: 0.33 | D5: Switch altar room background to 169_altar_clean_1acolytes
A6: =1.5*A5 | B6: 2 | C6: 0.33 | D6: Switch altar room background to 169_altar_clean_2acolytes
A7: =1.5*A6 | B7: 3 | C7: 0.33 | D7: Switch altar room background to 169_altar_clean_3acolytes
A8: =1.5*A7 | B8: 4 | C8: 0.33 | D8: Switch altar room background to 169_altar_clean_4acolytes
A9: L* 1.5 | B9: 5+ | C9: 0.33 | D9: beyond cap not shown visually. L is the threshold for the last acolyte, and the formula is rounded to the nearest integer.

Sheet Prob Tiers
A1: Probability Tier Authoring
A2: Modifiers are multiplicative weights on each base prob, then renormalised to 1.0. Base distributions MUST sum to 100%.
A4: Tier | B4: Colour (lore) | C4: Base weight (example) | D4: Normalised
A5: Stellar | B5: Crimson | C5: 0 | D5: =IF(SUM($C$5:$C$11)=0,0,C5/SUM($C$5:$C$11))
A6: Excellent | B6: Orange | C6: 0 | D6: =IF(SUM($C$5:$C$11)=0,0,C6/SUM($C$5:$C$11))
A7: Good | B7: Yellow | C7: 0 | D7: =IF(SUM($C$5:$C$11)=0,0,C7/SUM($C$5:$C$11))
A8: Neutral | B8: White | C8: 0 | D8: =IF(SUM($C$5:$C$11)=0,0,C8/SUM($C$5:$C$11))
A9: Bad | B9: Green | C9: 0 | D9: =IF(SUM($C$5:$C$11)=0,0,C9/SUM($C$5:$C$11))
A10: Terrible | B10: Church purple | C10: 0 | D10: =IF(SUM($C$5:$C$11)=0,0,C10/SUM($C$5:$C$11))
A11: Apocalyptic | B11: Light blue | C11: 0 | D11: =IF(SUM($C$5:$C$11)=0,0,C11/SUM($C$5:$C$11))
A12: SUM | C12: =SUM(C5:C11) | D12: =SUM(D5:D11)
A13: Renormalise lets raw weights be anything; normalised column always sums to 100%.
